Workbook

Sheet Instructions
A1: Brazilian Instagram Username Generator
A2: How to use:
A3: 1. Enter/edit first and last names in the Names sheet.
A4: 2. Add or change suffixes in the Suffixes sheet.
A5: 3. Generated automatically creates 1,000 candidates with shuffled format IDs.
A6: 4. Copy/paste values if you want to freeze a generated batch before recalculation.
A7: 5. Status can be changed to Available, Taken, or Pending.
A8: 6. The Duplicate? column flags repeated generated usernames.
A9: Note: Instagram availability is not verified by this workbook; use Instagram's own username field to confirm availability.

Sheet Names
A1: ID | B1: First Name | C1: Last Name | D1: Count
A2: 1 | B2: Caio | C2: Almeida | D2: 10
A3: 2 | B3: Lucas | C3: Santos | D3: 10
A4: 3 | B4: Enzo | C4: Oliveira | D4: 10
A5: 4 | B5: Kauan | C5: Costa | D5: 10
A6: 5 | B6: Vini | C6: Mendes | D6: 10
A7: 6 | B7: Pedro | C7: Rocha | D7: 10
A8: 7 | B8: Arthur | C8: Lima | D8: 10
A9: 8 | B9: Bruno | C9: Martins | D9: 10
A10: 9 | B10: Rafael | C10: Souza | D10: 10
A11: 10 | B11: Murilo | C11: Ferreira | D11: 10

Sheet Formats
A1: Format ID | B1: Format Name | C1: Pattern
A2: 1 | B2: First + Suffix | C2: {first}{suffix}
A3: 2 | B3: First + 2 Letters | C3: {first}{letters}
A4: 3 | B4: First + X + Suffix | C4: {first}x{suffix}
A5: 4 | B5: First + Double Letter | C5: {first}{double}
A6: 5 | B6: First + Rare Ending | C6: {first}{ending}
A7: 6 | B7: Short First + Suffix | C7: {shortfirst}{suffix}
A8: 7 | B8: First.Last | C8: {first}.{last}
A9: 8 | B9: First_Last | C9: {first}_{last}
A10: 9 | B10: First + Invented Ending | C10: {first}{invented}
A11: 10 | B11: First + Short Last | C11: {first}{shortlast}

Sheet Suffixes
A1: Suffix ID | B1: Suffix
A2: 1 | B2: zenn
A3: 2 | B3: vex
A4: 3 | B4: vyn
A5: 4 | B5: zaro
A6: 5 | B6: zyn
A7: 6 | B7: vexo
A8: 7 | B8: xyn
A9: 8 | B9: zov
A10: 9 | B10: rix
A11: 10 | B11: zen
A12: 11 | B12: varo
A13: 12 | B13: nex
... A31: 30 | B31: rizo

Sheet Generated
A1: ID | B1: First Name | C1: Last Name | D1: Format ID | E1: Random Seed | F1: Suffix | G1: Username | H1: Status | I1: Duplicate? | J1: Length | K1: Priority
A2: 1 | B2: =Names!B2 | C2: =Names!C2 | D2: =RANDBETWEEN(1,10) | E2: =RANDBETWEEN(1,30) | F2: =INDEX(Suffixes!$B$2:$B$31,E2) | G2: =LOWER(SUBSTITUTE(SUBSTITUTE(SUBSTITUTE(IF(D2=1,B2&F2,IF(D2=2,B2&LEFT(F2,2),IF(D2=3,B2&"x"&F2,IF(D2=4,B2&RIGHT(B2,1)&RIGHT(B2,1),IF(D2=5,B2&"vexo",IF(D2=6,LEFT(B2,MAX(3,LEN(B2)-2))&F2,IF(D2=7,B2&"."&C2,IF(D2=8,B2&"_"&C2,IF(D2=9,B2&"zaro",B2&LEFT(C2,4)))))))))," ",""),"á","a"),"ã","a")) | H2: Pending | I2: =IF(COUNTIF($G$2:$G$1001,G2)>1,"YES","NO") | J2: =LEN(G2) | K2: =IF(OR(D2=1,D2=5,D2=6,D2=9),3,IF(OR(D2=7,D2=8,D2=10),2,1))
A3: 2 | B3: =Names!B3 | C3: =Names!C3 | D3: =RANDBETWEEN(1,10) | E3: =RANDBETWEEN(1,30) | F3: =INDEX(Suffixes!$B$2:$B$31,E3) | G3: =LOWER(SUBSTITUTE(SUBSTITUTE(SUBSTITUTE(IF(D3=1,B3&F3,IF(D3=2,B3&LEFT(F3,2),IF(D3=3,B3&"x"&F3,IF(D3=4,B3&RIGHT(B3,1)&RIGHT(B3,1),IF(D3=5,B3&"vexo",IF(D3=6,LEFT(B3,MAX(3,LEN(B3)-2))&F3,IF(D3=7,B3&"."&C3,IF(D3=8,B3&"_"&C3,IF(D3=9,B3&"zaro",B3&LEFT(C3,4)))))))))," ",""),"á","a"),"ã","a")) | H3: Pending | I3: =IF(COUNTIF($G$2:$G$1001,G3)>1,"YES","NO") | J3: =LEN(G3) | K3: =IF(OR(D3=1,D3=5,D3=6,D3=9),3,IF(OR(D3=7,D3=8,D3=10),2,1))
A4: 3 | B4: =Names!B4 | C4: =Names!C4 | D4: =RANDBETWEEN(1,10) | E4: =RANDBETWEEN(1,30) | F4: =INDEX(Suffixes!$B$2:$B$31,E4) | G4: =LOWER(SUBSTITUTE(SUBSTITUTE(SUBSTITUTE(IF(D4=1,B4&F4,IF(D4=2,B4&LEFT(F4,2),IF(D4=3,B4&"x"&F4,IF(D4=4,B4&RIGHT(B4,1)&RIGHT(B4,1),IF(D4=5,B4&"vexo",IF(D4=6,LEFT(B4,MAX(3,LEN(B4)-2))&F4,IF(D4=7,B4&"."&C4,IF(D4=8,B4&"_"&C4,IF(D4=9,B4&"zaro",B4&LEFT(C4,4)))))))))," ",""),"á","a"),"ã","a")) | H4: Pending | I4: =IF(COUNTIF($G$2:$G$1001,G4)>1,"YES","NO") | J4: =LEN(G4) | K4: =IF(OR(D4=1,D4=5,D4=6,D4=9),3,IF(OR(D4=7,D4=8,D4=10),2,1))
A5: 4 | B5: =Names!B5 | C5: =Names!C5 | D5: =RANDBETWEEN(1,10) | E5: =RANDBETWEEN(1,30) | F5: =INDEX(Suffixes!$B$2:$B$31,E5) | G5: =LOWER(SUBSTITUTE(SUBSTITUTE(SUBSTITUTE(IF(D5=1,B5&F5,IF(D5=2,B5&LEFT(F5,2),IF(D5=3,B5&"x"&F5,IF(D5=4,B5&RIGHT(B5,1)&RIGHT(B5,1),IF(D5=5,B5&"vexo",IF(D5=6,LEFT(B5,MAX(3,LEN(B5)-2))&F5,IF(D5=7,B5&"."&C5,IF(D5=8,B5&"_"&C5,IF(D5=9,B5&"zaro",B5&LEFT(C5,4)))))))))," ",""),"á","a"),"ã","a")) | H5: Pending | I5: =IF(COUNTIF($G$2:$G$1001,G5)>1,"YES","NO") | J5: =LEN(G5) | K5: =IF(OR(D5=1,D5=5,D5=6,D5=9),3,IF(OR(D5=7,D5=8,D5=10),2,1))
A6: 5 | B6: =Names!B6 | C6: =Names!C6 | D6: =RANDBETWEEN(1,10) | E6: =RANDBETWEEN(1,30) | F6: =INDEX(Suffixes!$B$2:$B$31,E6) | G6: =LOWER(SUBSTITUTE(SUBSTITUTE(SUBSTITUTE(IF(D6=1,B6&F6,IF(D6=2,B6&LEFT(F6,2),IF(D6=3,B6&"x"&F6,IF(D6=4,B6&RIGHT(B6,1)&RIGHT(B6,1),IF(D6=5,B6&"vexo",IF(D6=6,LEFT(B6,MAX(3,LEN(B6)-2))&F6,IF(D6=7,B6&"."&C6,IF(D6=8,B6&"_"&C6,IF(D6=9,B6&"zaro",B6&LEFT(C6,4)))))))))," ",""),"á","a"),"ã","a")) | H6: Pending | I6: =IF(COUNTIF($G$2:$G$1001,G6)>1,"YES","NO") | J6: =LEN(G6) | K6: =IF(OR(D6=1,D6=5,D6=6,D6=9),3,IF(OR(D6=7,D6=8,D6=10),2,1))
A7: 6 | B7: =Names!B7 | C7: =Names!C7 | D7: =RANDBETWEEN(1,10) | E7: =RANDBETWEEN(1,30) | F7: =INDEX(Suffixes!$B$2:$B$31,E7) | G7: =LOWER(SUBSTITUTE(SUBSTITUTE(SUBSTITUTE(IF(D7=1,B7&F7,IF(D7=2,B7&LEFT(F7,2),IF(D7=3,B7&"x"&F7,IF(D7=4,B7&RIGHT(B7,1)&RIGHT(B7,1),IF(D7=5,B7&"vexo",IF(D7=6,LEFT(B7,MAX(3,LEN(B7)-2))&F7,IF(D7=7,B7&"."&C7,IF(D7=8,B7&"_"&C7,IF(D7=9,B7&"zaro",B7&LEFT(C7,4)))))))))," ",""),"á","a"),"ã","a")) | H7: Pending | I7: =IF(COUNTIF($G$2:$G$1001,G7)>1,"YES","NO") | J7: =LEN(G7) | K7: =IF(OR(D7=1,D7=5,D7=6,D7=9),3,IF(OR(D7=7,D7=8,D7=10),2,1))
A8: 7 | B8: =Names!B8 | C8: =Names!C8 | D8: =RANDBETWEEN(1,10) | E8: =RANDBETWEEN(1,30) | F8: =INDEX(Suffixes!$B$2:$B$31,E8) | G8: =LOWER(SUBSTITUTE(SUBSTITUTE(SUBSTITUTE(IF(D8=1,B8&F8,IF(D8=2,B8&LEFT(F8,2),IF(D8=3,B8&"x"&F8,IF(D8=4,B8&RIGHT(B8,1)&RIGHT(B8,1),IF(D8=5,B8&"vexo",IF(D8=6,LEFT(B8,MAX(3,LEN(B8)-2))&F8,IF(D8=7,B8&"."&C8,IF(D8=8,B8&"_"&C8,IF(D8=9,B8&"zaro",B8&LEFT(C8,4)))))))))," ",""),"á","a"),"ã","a")) | H8: Pending | I8: =IF(COUNTIF($G$2:$G$1001,G8)>1,"YES","NO") | J8: =LEN(G8) | K8: =IF(OR(D8=1,D8=5,D8=6,D8=9),3,IF(OR(D8=7,D8=8,D8=10),2,1))
A9: 8 | B9: =Names!B9 | C9: =Names!C9 | D9: =RANDBETWEEN(1,10) | E9: =RANDBETWEEN(1,30) | F9: =INDEX(Suffixes!$B$2:$B$31,E9) | G9: =LOWER(SUBSTITUTE(SUBSTITUTE(SUBSTITUTE(IF(D9=1,B9&F9,IF(D9=2,B9&LEFT(F9,2),IF(D9=3,B9&"x"&F9,IF(D9=4,B9&RIGHT(B9,1)&RIGHT(B9,1),IF(D9=5,B9&"vexo",IF(D9=6,LEFT(B9,MAX(3,LEN(B9)-2))&F9,IF(D9=7,B9&"."&C9,IF(D9=8,B9&"_"&C9,IF(D9=9,B9&"zaro",B9&LEFT(C9,4)))))))))," ",""),"á","a"),"ã","a")) | H9: Pending | I9: =IF(COUNTIF($G$2:$G$1001,G9)>1,"YES","NO") | J9: =LEN(G9) | K9: =IF(OR(D9=1,D9=5,D9=6,D9=9),3,IF(OR(D9=7,D9=8,D9=10),2,1))
A10: 9 | B10: =Names!B10 | C10: =Names!C10 | D10: =RANDBETWEEN(1,10) | E10: =RANDBETWEEN(1,30) | F10: =INDEX(Suffixes!$B$2:$B$31,E10) | G10: =LOWER(SUBSTITUTE(SUBSTITUTE(SUBSTITUTE(IF(D10=1,B10&F10,IF(D10=2,B10&LEFT(F10,2),IF(D10=3,B10&"x"&F10,IF(D10=4,B10&RIGHT(B10,1)&RIGHT(B10,1),IF(D10=5,B10&"vexo",IF(D10=6,LEFT(B10,MAX(3,LEN(B10)-2))&F10,IF(D10=7,B10&"."&C10,IF(D10=8,B10&"_"&C10,IF(D10=9,B10&"zaro",B10&LEFT(C10,4)))))))))," ",""),"á","a"),"ã","a")) | H10: Pending | I10: =IF(COUNTIF($G$2:$G$1001,G10)>1,"YES","NO") | J10: =LEN(G10) | K10: =IF(OR(D10=1,D10=5,D10=6,D10=9),3,IF(OR(D10=7,D10=8,D10=10),2,1))
A11: 10 | B11: =Names!B11 | C11: =Names!C11 | D11: =RANDBETWEEN(1,10) | E11: =RANDBETWEEN(1,30) | F11: =INDEX(Suffixes!$B$2:$B$31,E11) | G11: =LOWER(SUBSTITUTE(SUBSTITUTE(SUBSTITUTE(IF(D11=1,B11&F11,IF(D11=2,B11&LEFT(F11,2),IF(D11=3,B11&"x"&F11,IF(D11=4,B11&RIGHT(B11,1)&RIGHT(B11,1),IF(D11=5,B11&"vexo",IF(D11=6,LEFT(B11,MAX(3,LEN(B11)-2))&F11,IF(D11=7,B11&"."&C11,IF(D11=8,B11&"_"&C11,IF(D11=9,B11&"zaro",B11&LEFT(C11,4)))))))))," ",""),"á","a"),"ã","a")) | H11: Pending | I11: =IF(COUNTIF($G$2:$G$1001,G11)>1,"YES","NO") | J11: =LEN(G11) | K11: =IF(OR(D11=1,D11=5,D11=6,D11=9),3,IF(OR(D11=7,D11=8,D11=10),2,1))
A12: 11 | B12: =Names!B12 | C12: =Names!C12 | D12: =RANDBETWEEN(1,10) | E12: =RANDBETWEEN(1,30) | F12: =INDEX(Suffixes!$B$2:$B$31,E12) | G12: =LOWER(SUBSTITUTE(SUBSTITUTE(SUBSTITUTE(IF(D12=1,B12&F12,IF(D12=2,B12&LEFT(F12,2),IF(D12=3,B12&"x"&F12,IF(D12=4,B12&RIGHT(B12,1)&RIGHT(B12,1),IF(D12=5,B12&"vexo",IF(D12=6,LEFT(B12,MAX(3,LEN(B12)-2))&F12,IF(D12=7,B12&"."&C12,IF(D12=8,B12&"_"&C12,IF(D12=9,B12&"zaro",B12&LEFT(C12,4)))))))))," ",""),"á","a"),"ã","a")) | H12: Pending | I12: =IF(COUNTIF($G$2:$G$1001,G12)>1,"YES","NO") | J12: =LEN(G12) | K12: =IF(OR(D12=1,D12=5,D12=6,D12=9),3,IF(OR(D12=7,D12=8,D12=10),2,1))
A13: 12 | B13: =Names!B13 | C13: =Names!C13 | D13: =RANDBETWEEN(1,10) | E13: =RANDBETWEEN(1,30) | F13: =INDEX(Suffixes!$B$2:$B$31,E13) | G13: =LOWER(SUBSTITUTE(SUBSTITUTE(SUBSTITUTE(IF(D13=1,B13&F13,IF(D13=2,B13&LEFT(F13,2),IF(D13=3,B13&"x"&F13,IF(D13=4,B13&RIGHT(B13,1)&RIGHT(B13,1),IF(D13=5,B13&"vexo",IF(D13=6,LEFT(B13,MAX(3,LEN(B13)-2))&F13,IF(D13=7,B13&"."&C13,IF(D13=8,B13&"_"&C13,IF(D13=9,B13&"zaro",B13&LEFT(C13,4)))))))))," ",""),"á","a"),"ã","a")) | H13: Pending | I13: =IF(COUNTIF($G$2:$G$1001,G13)>1,"YES","NO") | J13: =LEN(G13) | K13: =IF(OR(D13=1,D13=5,D13=6,D13=9),3,IF(OR(D13=7,D13=8,D13=10),2,1))
... A101: 100 | B101: =Names!B101 | C101: =Names!C101 | D101: =RANDBETWEEN(1,10) | E101: =RANDBETWEEN(1,30) | F101: =INDEX(Suffixes!$B$2:$B$31,E101) | G101: =LOWER(SUBSTITUTE(SUBSTITUTE(SUBSTITUTE(IF(D101=1,B101&F101,IF(D101=2,B101&LEFT(F101,2),IF(D101=3,B101&"x"&F101,IF(D101=4,B101&RIGHT(B101,1)&RIGHT(B101,1),IF(D101=5,B101&"vexo",IF(D101=6,LEFT(B101,MAX(3,LEN(B101)-2))&F101,IF(D101=7,B101&"."&C101,IF(D101=8,B101&"_"&C101,IF(D101=9,B101&"zaro",B101&LEFT(C101,4)))))))))," ",""),"á","a"),"ã","a")) | H101: Pending | I101: =IF(COUNTIF($G$2:$G$1001,G101)>1,"YES","NO") | J101: =LEN(G101) | K101: =IF(OR(D101=1,D101=5,D101=6,D101=9),3,IF(OR(D101=7,D101=8,D101=10),2,1))
A102: 101 | B102: =Names!B2 | C102: =Names!C2 | D102: =RANDBETWEEN(1,10) | E102: =RANDBETWEEN(1,30) | F102: =INDEX(Suffixes!$B$2:$B$31,E102) | G102: =LOWER(SUBSTITUTE(SUBSTITUTE(SUBSTITUTE(IF(D102=1,B102&F102,IF(D102=2,B102&LEFT(F102,2),IF(D102=3,B102&"x"&F102,IF(D102=4,B102&RIGHT(B102,1)&RIGHT(B102,1),IF(D102=5,B102&"vexo",IF(D102=6,LEFT(B102,MAX(3,LEN(B102)-2))&F102,IF(D102=7,B102&"."&C102,IF(D102=8,B102&"_"&C102,IF(D102=9,B102&"zaro",B102&LEFT(C102,4)))))))))," ",""),"á","a"),"ã","a")) | H102: Pending | I102: =IF(COUNTIF($G$2:$G$1001,G102)>1,"YES","NO") | J102: =LEN(G102) | K102: =IF(OR(D102=1,D102=5,D102=6,D102=9),3,IF(OR(D102=7,D102=8,D102=10),2,1))
A103: 102 | B103: =Names!B3 | C103: =Names!C3 | D103: =RANDBETWEEN(1,10) | E103: =RANDBETWEEN(1,30) | F103: =INDEX(Suffixes!$B$2:$B$31,E103) | G103: =LOWER(SUBSTITUTE(SUBSTITUTE(SUBSTITUTE(IF(D103=1,B103&F103,IF(D103=2,B103&LEFT(F103,2),IF(D103=3,B103&"x"&F103,IF(D103=4,B103&RIGHT(B103,1)&RIGHT(B103,1),IF(D103=5,B103&"vexo",IF(D103=6,LEFT(B103,MAX(3,LEN(B103)-2))&F103,IF(D103=7,B103&"."&C103,IF(D103=8,B103&"_"&C103,IF(D103=9,B103&"zaro",B103&LEFT(C103,4)))))))))," ",""),"á","a"),"ã","a")) | H103: Pending | I103: =IF(COUNTIF($G$2:$G$1001,G103)>1,"YES","NO") | J103: =LEN(G103) | K103: =IF(OR(D103=1,D103=5,D103=6,D103=9),3,IF(OR(D103=7,D103=8,D103=10),2,1))
A104: 103 | B104: =Names!B4 | C104: =Names!C4 | D104: =RANDBETWEEN(1,10) | E104: =RANDBETWEEN(1,30) | F104: =INDEX(Suffixes!$B$2:$B$31,E104) | G104: =LOWER(SUBSTITUTE(SUBSTITUTE(SUBSTITUTE(IF(D104=1,B104&F104,IF(D104=2,B104&LEFT(F104,2),IF(D104=3,B104&"x"&F104,IF(D104=4,B104&RIGHT(B104,1)&RIGHT(B104,1),IF(D104=5,B104&"vexo",IF(D104=6,LEFT(B104,MAX(3,LEN(B104)-2))&F104,IF(D104=7,B104&"."&C104,IF(D104=8,B104&"_"&C104,IF(D104=9,B104&"zaro",B104&LEFT(C104,4)))))))))," ",""),"á","a"),"ã","a")) | H104: Pending | I104: =IF(COUNTIF($G$2:$G$1001,G104)>1,"YES","NO") | J104: =LEN(G104) | K104: =IF(OR(D104=1,D104=5,D104=6,D104=9),3,IF(OR(D104=7,D104=8,D104=10),2,1))
A105: 104 | B105: =Names!B5 | C105: =Names!C5 | D105: =RANDBETWEEN(1,10) | E105: =RANDBETWEEN(1,30) | F105: =INDEX(Suffixes!$B$2:$B$31,E105) | G105: =LOWER(SUBSTITUTE(SUBSTITUTE(SUBSTITUTE(IF(D105=1,B105&F105,IF(D105=2,B105&LEFT(F105,2),IF(D105=3,B105&"x"&F105,IF(D105=4,B105&RIGHT(B105,1)&RIGHT(B105,1),IF(D105=5,B105&"vexo",IF(D105=6,LEFT(B105,MAX(3,LEN(B105)-2))&F105,IF(D105=7,B105&"."&C105,IF(D105=8,B105&"_"&C105,IF(D105=9,B105&"zaro",B105&LEFT(C105,4)))))))))," ",""),"á","a"),"ã","a")) | H105: Pending | I105: =IF(COUNTIF($G$2:$G$1001,G105)>1,"YES","NO") | J105: =LEN(G105) | K105: =IF(OR(D105=1,D105=5,D105=6,D105=9),3,IF(OR(D105=7,D105=8,D105=10),2,1))
A106: 105 | B106: =Names!B6 | C106: =Names!C6 | D106: =RANDBETWEEN(1,10) | E106: =RANDBETWEEN(1,30) | F106: =INDEX(Suffixes!$B$2:$B$31,E106) | G106: =LOWER(SUBSTITUTE(SUBSTITUTE(SUBSTITUTE(IF(D106=1,B106&F106,IF(D106=2,B106&LEFT(F106,2),IF(D106=3,B106&"x"&F106,IF(D106=4,B106&RIGHT(B106,1)&RIGHT(B106,1),IF(D106=5,B106&"vexo",IF(D106=6,LEFT(B106,MAX(3,LEN(B106)-2))&F106,IF(D106=7,B106&"."&C106,IF(D106=8,B106&"_"&C106,IF(D106=9,B106&"zaro",B106&LEFT(C106,4)))))))))," ",""),"á","a"),"ã","a")) | H106: Pending | I106: =IF(COUNTIF($G$2:$G$1001,G106)>1,"YES","NO") | J106: =LEN(G106) | K106: =IF(OR(D106=1,D106=5,D106=6,D106=9),3,IF(OR(D106=7,D106=8,D106=10),2,1))
A107: 106 | B107: =Names!B7 | C107: =Names!C7 | D107: =RANDBETWEEN(1,10) | E107: =RANDBETWEEN(1,30) | F107: =INDEX(Suffixes!$B$2:$B$31,E107) | G107: =LOWER(SUBSTITUTE(SUBSTITUTE(SUBSTITUTE(IF(D107=1,B107&F107,IF(D107=2,B107&LEFT(F107,2),IF(D107=3,B107&"x"&F107,IF(D107=4,B107&RIGHT(B107,1)&RIGHT(B107,1),IF(D107=5,B107&"vexo",IF(D107=6,LEFT(B107,MAX(3,LEN(B107)-2))&F107,IF(D107=7,B107&"."&C107,IF(D107=8,B107&"_"&C107,IF(D107=9,B107&"zaro",B107&LEFT(C107,4)))))))))," ",""),"á","a"),"ã","a")) | H107: Pending | I107: =IF(COUNTIF($G$2:$G$1001,G107)>1,"YES","NO") | J107: =LEN(G107) | K107: =IF(OR(D107=1,D107=5,D107=6,D107=9),3,IF(OR(D107=7,D107=8,D107=10),2,1))
A108: 107 | B108: =Names!B8 | C108: =Names!C8 | D108: =RANDBETWEEN(1,10) | E108: =RANDBETWEEN(1,30) | F108: =INDEX(Suffixes!$B$2:$B$31,E108) | G108: =LOWER(SUBSTITUTE(SUBSTITUTE(SUBSTITUTE(IF(D108=1,B108&F108,IF(D108=2,B108&LEFT(F108,2),IF(D108=3,B108&"x"&F108,IF(D108=4,B108&RIGHT(B108,1)&RIGHT(B108,1),IF(D108=5,B108&"vexo",IF(D108=6,LEFT(B108,MAX(3,LEN(B108)-2))&F108,IF(D108=7,B108&"."&C108,IF(D108=8,B108&"_"&C108,IF(D108=9,B108&"zaro",B108&LEFT(C108,4)))))))))," ",""),"á","a"),"ã","a")) | H108: Pending | I108: =IF(COUNTIF($G$2:$G$1001,G108)>1,"YES","NO") | J108: =LEN(G108) | K108: =IF(OR(D108=1,D108=5,D108=6,D108=9),3,IF(OR(D108=7,D108=8,D108=10),2,1))
A109: 108 | B109: =Names!B9 | C109: =Names!C9 | D109: =RANDBETWEEN(1,10) | E109: =RANDBETWEEN(1,30) | F109: =INDEX(Suffixes!$B$2:$B$31,E109) | G109: =LOWER(SUBSTITUTE(SUBSTITUTE(SUBSTITUTE(IF(D109=1,B109&F109,IF(D109=2,B109&LEFT(F109,2),IF(D109=3,B109&"x"&F109,IF(D109=4,B109&RIGHT(B109,1)&RIGHT(B109,1),IF(D109=5,B109&"vexo",IF(D109=6,LEFT(B109,MAX(3,LEN(B109)-2))&F109,IF(D109=7,B109&"."&C109,IF(D109=8,B109&"_"&C109,IF(D109=9,B109&"zaro",B109&LEFT(C109,4)))))))))," ",""),"á","a"),"ã","a")) | H109: Pending | I109: =IF(COUNTIF($G$2:$G$1001,G109)>1,"YES","NO") | J109: =LEN(G109) | K109: =IF(OR(D109=1,D109=5,D109=6,D109=9),3,IF(OR(D109=7,D109=8,D109=10),2,1))
A110: 109 | B110: =Names!B10 | C110: =Names!C10 | D110: =RANDBETWEEN(1,10) | E110: =RANDBETWEEN(1,30) | F110: =INDEX(Suffixes!$B$2:$B$31,E110) | G110: =LOWER(SUBSTITUTE(SUBSTITUTE(SUBSTITUTE(IF(D110=1,B110&F110,IF(D110=2,B110&LEFT(F110,2),IF(D110=3,B110&"x"&F110,IF(D110=4,B110&RIGHT(B110,1)&RIGHT(B110,1),IF(D110=5,B110&"vexo",IF(D110=6,LEFT(B110,MAX(3,LEN(B110)-2))&F110,IF(D110=7,B110&"."&C110,IF(D110=8,B110&"_"&C110,IF(D110=9,B110&"zaro",B110&LEFT(C110,4)))))))))," ",""),"á","a"),"ã","a")) | H110: Pending | I110: =IF(COUNTIF($G$2:$G$1001,G110)>1,"YES","NO") | J110: =LEN(G110) | K110: =IF(OR(D110=1,D110=5,D110=6,D110=9),3,IF(OR(D110=7,D110=8,D110=10),2,1))
A111: 110 | B111: =Names!B11 | C111: =Names!C11 | D111: =RANDBETWEEN(1,10) | E111: =RANDBETWEEN(1,30) | F111: =INDEX(Suffixes!$B$2:$B$31,E111) | G111: =LOWER(SUBSTITUTE(SUBSTITUTE(SUBSTITUTE(IF(D111=1,B111&F111,IF(D111=2,B111&LEFT(F111,2),IF(D111=3,B111&"x"&F111,IF(D111=4,B111&RIGHT(B111,1)&RIGHT(B111,1),IF(D111=5,B111&"vexo",IF(D111=6,LEFT(B111,MAX(3,LEN(B111)-2))&F111,IF(D111=7,B111&"."&C111,IF(D111=8,B111&"_"&C111,IF(D111=9,B111&"zaro",B111&LEFT(C111,4)))))))))," ",""),"á","a"),"ã","a")) | H111: Pending | I111: =IF(COUNTIF($G$2:$G$1001,G111)>1,"YES","NO") | J111: =LEN(G111) | K111: =IF(OR(D111=1,D111=5,D111=6,D111=9),3,IF(OR(D111=7,D111=8,D111=10),2,1))
A112: 111 | B112: =Names!B12 | C112: =Names!C12 | D112: =RANDBETWEEN(1,10) | E112: =RANDBETWEEN(1,30) | F112: =INDEX(Suffixes!$B$2:$B$31,E112) | G112: =LOWER(SUBSTITUTE(SUBSTITUTE(SUBSTITUTE(IF(D112=1,B112&F112,IF(D112=2,B112&LEFT(F112,2),IF(D112=3,B112&"x"&F112,IF(D112=4,B112&RIGHT(B112,1)&RIGHT(B112,1),IF(D112=5,B112&"vexo",IF(D112=6,LEFT(B112,MAX(3,LEN(B112)-2))&F112,IF(D112=7,B112&"."&C112,IF(D112=8,B112&"_"&C112,IF(D112=9,B112&"zaro",B112&LEFT(C112,4)))))))))," ",""),"á","a"),"ã","a")) | H112: Pending | I112: =IF(COUNTIF($G$2:$G$1001,G112)>1,"YES","NO") | J112: =LEN(G112) | K112: =IF(OR(D112=1,D112=5,D112=6,D112=9),3,IF(OR(D112=7,D112=8,D112=10),2,1))
A113: 112 | B113: =Names!B13 | C113: =Names!C13 | D113: =RANDBETWEEN(1,10) | E113: =RANDBETWEEN(1,30) | F113: =INDEX(Suffixes!$B$2:$B$31,E113) | G113: =LOWER(SUBSTITUTE(SUBSTITUTE(SUBSTITUTE(IF(D113=1,B113&F113,IF(D113=2,B113&LEFT(F113,2),IF(D113=3,B113&"x"&F113,IF(D113=4,B113&RIGHT(B113,1)&RIGHT(B113,1),IF(D113=5,B113&"vexo",IF(D113=6,LEFT(B113,MAX(3,LEN(B113)-2))&F113,IF(D113=7,B113&"."&C113,IF(D113=8,B113&"_"&C113,IF(D113=9,B113&"zaro",B113&LEFT(C113,4)))))))))," ",""),"á","a"),"ã","a")) | H113: Pending | I113: =IF(COUNTIF($G$2:$G$1001,G113)>1,"YES","NO") | J113: =LEN(G113) | K113: =IF(OR(D113=1,D113=5,D113=6,D113=9),3,IF(OR(D113=7,D113=8,D113=10),2,1))
... A201: 200 | B201: =Names!B101 | C201: =Names!C101 | D201: =RANDBETWEEN(1,10) | E201: =RANDBETWEEN(1,30) | F201: =INDEX(Suffixes!$B$2:$B$31,E201) | G201: =LOWER(SUBSTITUTE(SUBSTITUTE(SUBSTITUTE(IF(D201=1,B201&F201,IF(D201=2,B201&LEFT(F201,2),IF(D201=3,B201&"x"&F201,IF(D201=4,B201&RIGHT(B201,1)&RIGHT(B201,1),IF(D201=5,B201&"vexo",IF(D201=6,LEFT(B201,MAX(3,LEN(B201)-2))&F201,IF(D201=7,B201&"."&C201,IF(D201=8,B201&"_"&C201,IF(D201=9,B201&"zaro",B201&LEFT(C201,4)))))))))," ",""),"á","a"),"ã","a")) | H201: Pending | I201: =IF(COUNTIF($G$2:$G$1001,G201)>1,"YES","NO") | J201: =LEN(G201) | K201: =IF(OR(D201=1,D201=5,D201=6,D201=9),3,IF(OR(D201=7,D201=8,D201=10),2,1))
A202: 201 | B202: =Names!B2 | C202: =Names!C2 | D202: =RANDBETWEEN(1,10) | E202: =RANDBETWEEN(1,30) | F202: =INDEX(Suffixes!$B$2:$B$31,E202) | G202: =LOWER(SUBSTITUTE(SUBSTITUTE(SUBSTITUTE(IF(D202=1,B202&F202,IF(D202=2,B202&LEFT(F202,2),IF(D202=3,B202&"x"&F202,IF(D202=4,B202&RIGHT(B202,1)&RIGHT(B202,1),IF(D202=5,B202&"vexo",IF(D202=6,LEFT(B202,MAX(3,LEN(B202)-2))&F202,IF(D202=7,B202&"."&C202,IF(D202=8,B202&"_"&C202,IF(D202=9,B202&"zaro",B202&LEFT(C202,4)))))))))," ",""),"á","a"),"ã","a")) | H202: Pending | I202: =IF(COUNTIF($G$2:$G$1001,G202)>1,"YES","NO") | J202: =LEN(G202) | K202: =IF(OR(D202=1,D202=5,D202=6,D202=9),3,IF(OR(D202=7,D202=8,D202=10),2,1))
A203: 202 | B203: =Names!B3 | C203: =Names!C3 | D203: =RANDBETWEEN(1,10) | E203: =RANDBETWEEN(1,30) | F203: =INDEX(Suffixes!$B$2:$B$31,E203) | G203: =LOWER(SUBSTITUTE(SUBSTITUTE(SUBSTITUTE(IF(D203=1,B203&F203,IF(D203=2,B203&LEFT(F203,2),IF(D203=3,B203&"x"&F203,IF(D203=4,B203&RIGHT(B203,1)&RIGHT(B203,1),IF(D203=5,B203&"vexo",IF(D203=6,LEFT(B203,MAX(3,LEN(B203)-2))&F203,IF(D203=7,B203&"."&C203,IF(D203=8,B203&"_"&C203,IF(D203=9,B203&"zaro",B203&LEFT(C203,4)))))))))," ",""),"á","a"),"ã","a")) | H203: Pending | I203: =IF(COUNTIF($G$2:$G$1001,G203)>1,"YES","NO") | J203: =LEN(G203) | K203: =IF(OR(D203=1,D203=5,D203=6,D203=9),3,IF(OR(D203=7,D203=8,D203=10),2,1))
A204: 203 | B204: =Names!B4 | C204: =Names!C4 | D204: =RANDBETWEEN(1,10) | E204: =RANDBETWEEN(1,30) | F204: =INDEX(Suffixes!$B$2:$B$31,E204) | G204: =LOWER(SUBSTITUTE(SUBSTITUTE(SUBSTITUTE(IF(D204=1,B204&F204,IF(D204=2,B204&LEFT(F204,2),IF(D204=3,B204&"x"&F204,IF(D204=4,B204&RIGHT(B204,1)&RIGHT(B204,1),IF(D204=5,B204&"vexo",IF(D204=6,LEFT(B204,MAX(3,LEN(B204)-2))&F204,IF(D204=7,B204&"."&C204,IF(D204=8,B204&"_"&C204,IF(D204=9,B204&"zaro",B204&LEFT(C204,4)))))))))," ",""),"á","a"),"ã","a")) | H204: Pending | I204: =IF(COUNTIF($G$2:$G$1001,G204)>1,"YES","NO") | J204: =LEN(G204) | K204: =IF(OR(D204=1,D204=5,D204=6,D204=9),3,IF(OR(D204=7,D204=8,D204=10),2,1))
A205: 204 | B205: =Names!B5 | C205: =Names!C5 | D205: =RANDBETWEEN(1,10) | E205: =RANDBETWEEN(1,30) | F205: =INDEX(Suffixes!$B$2:$B$31,E205) | G205: =LOWER(SUBSTITUTE(SUBSTITUTE(SUBSTITUTE(IF(D205=1,B205&F205,IF(D205=2,B205&LEFT(F205,2),IF(D205=3,B205&"x"&F205,IF(D205=4,B205&RIGHT(B205,1)&RIGHT(B205,1),IF(D205=5,B205&"vexo",IF(D205=6,LEFT(B205,MAX(3,LEN(B205)-2))&F205,IF(D205=7,B205&"."&C205,IF(D205=8,B205&"_"&C205,IF(D205=9,B205&"zaro",B205&LEFT(C205,4)))))))))," ",""),"á","a"),"ã","a")) | H205: Pending | I205: =IF(COUNTIF($G$2:$G$1001,G205)>1,"YES","NO") | J205: =LEN(G205) | K205: =IF(OR(D205=1,D205=5,D205=6,D205=9),3,IF(OR(D205=7,D205=8,D205=10),2,1))
A206: 205 | B206: =Names!B6 | C206: =Names!C6 | D206: =RANDBETWEEN(1,10) | E206: =RANDBETWEEN(1,30) | F206: =INDEX(Suffixes!$B$2:$B$31,E206) | G206: =LOWER(SUBSTITUTE(SUBSTITUTE(SUBSTITUTE(IF(D206=1,B206&F206,IF(D206=2,B206&LEFT(F206,2),IF(D206=3,B206&"x"&F206,IF(D206=4,B206&RIGHT(B206,1)&RIGHT(B206,1),IF(D206=5,B206&"vexo",IF(D206=6,LEFT(B206,MAX(3,LEN(B206)-2))&F206,IF(D206=7,B206&"."&C206,IF(D206=8,B206&"_"&C206,IF(D206=9,B206&"zaro",B206&LEFT(C206,4)))))))))," ",""),"á","a"),"ã","a")) | H206: Pending | I206: =IF(COUNTIF($G$2:$G$1001,G206)>1,"YES","NO") | J206: =LEN(G206) | K206: =IF(OR(D206=1,D206=5,D206=6,D206=9),3,IF(OR(D206=7,D206=8,D206=10),2,1))
A207: 206 | B207: =Names!B7 | C207: =Names!C7 | D207: =RANDBETWEEN(1,10) | E207: =RANDBETWEEN(1,30) | F207: =INDEX(Suffixes!$B$2:$B$31,E207) | G207: =LOWER(SUBSTITUTE(SUBSTITUTE(SUBSTITUTE(IF(D207=1,B207&F207,IF(D207=2,B207&LEFT(F207,2),IF(D207=3,B207&"x"&F207,IF(D207=4,B207&RIGHT(B207,1)&RIGHT(B207,1),IF(D207=5,B207&"vexo",IF(D207=6,LEFT(B207,MAX(3,LEN(B207)-2))&F207,IF(D207=7,B207&"."&C207,IF(D207=8,B207&"_"&C207,IF(D207=9,B207&"zaro",B207&LEFT(C207,4)))))))))," ",""),"á","a"),"ã","a")) | H207: Pending | I207: =IF(COUNTIF($G$2:$G$1001,G207)>1,"YES","NO") | J207: =LEN(G207) | K207: =IF(OR(D207=1,D207=5,D207=6,D207=9),3,IF(OR(D207=7,D207=8,D207=10),2,1))
A208: 207 | B208: =Names!B8 | C208: =Names!C8 | D208: =RANDBETWEEN(1,10) | E208: =RANDBETWEEN(1,30) | F208: =INDEX(Suffixes!$B$2:$B$31,E208) | G208: =LOWER(SUBSTITUTE(SUBSTITUTE(SUBSTITUTE(IF(D208=1,B208&F208,IF(D208=2,B208&LEFT(F208,2),IF(D208=3,B208&"x"&F208,IF(D208=4,B208&RIGHT(B208,1)&RIGHT(B208,1),IF(D208=5,B208&"vexo",IF(D208=6,LEFT(B208,MAX(3,LEN(B208)-2))&F208,IF(D208=7,B208&"."&C208,IF(D208=8,B208&"_"&C208,IF(D208=9,B208&"zaro",B208&LEFT(C208,4)))))))))," ",""),"á","a"),"ã","a")) | H208: Pending | I208: =IF(COUNTIF($G$2:$G$1001,G208)>1,"YES","NO") | J208: =LEN(G208) | K208: =IF(OR(D208=1,D208=5,D208=6,D208=9),3,IF(OR(D208=7,D208=8,D208=10),2,1))
A209: 208 | B209: =Names!B9 | C209: =Names!C9 | D209: =RANDBETWEEN(1,10) | E209: =RANDBETWEEN(1,30) | F209: =INDEX(Suffixes!$B$2:$B$31,E209) | G209: =LOWER(SUBSTITUTE(SUBSTITUTE(SUBSTITUTE(IF(D209=1,B209&F209,IF(D209=2,B209&LEFT(F209,2),IF(D209=3,B209&"x"&F209,IF(D209=4,B209&RIGHT(B209,1)&RIGHT(B209,1),IF(D209=5,B209&"vexo",IF(D209=6,LEFT(B209,MAX(3,LEN(B209)-2))&F209,IF(D209=7,B209&"."&C209,IF(D209=8,B209&"_"&C209,IF(D209=9,B209&"zaro",B209&LEFT(C209,4)))))))))," ",""),"á","a"),"ã","a")) | H209: Pending | I209: =IF(COUNTIF($G$2:$G$1001,G209)>1,"YES","NO") | J209: =LEN(G209) | K209: =IF(OR(D209=1,D209=5,D209=6,D209=9),3,IF(OR(D209=7,D209=8,D209=10),2,1))
A210: 209 | B210: =Names!B10 | C210: =Names!C10 | D210: =RANDBETWEEN(1,10) | E210: =RANDBETWEEN(1,30) | F210: =INDEX(Suffixes!$B$2:$B$31,E210) | G210: =LOWER(SUBSTITUTE(SUBSTITUTE(SUBSTITUTE(IF(D210=1,B210&F210,IF(D210=2,B210&LEFT(F210,2),IF(D210=3,B210&"x"&F210,IF(D210=4,B210&RIGHT(B210,1)&RIGHT(B210,1),IF(D210=5,B210&"vexo",IF(D210=6,LEFT(B210,MAX(3,LEN(B210)-2))&F210,IF(D210=7,B210&"."&C210,IF(D210=8,B210&"_"&C210,IF(D210=9,B210&"zaro",B210&LEFT(C210,4)))))))))," ",""),"á","a"),"ã","a")) | H210: Pending | I210: =IF(COUNTIF($G$2:$G$1001,G210)>1,"YES","NO") | J210: =LEN(G210) | K210: =IF(OR(D210=1,D210=5,D210=6,D210=9),3,IF(OR(D210=7,D210=8,D210=10),2,1))
A211: 210 | B211: =Names!B11 | C211: =Names!C11 | D211: =RANDBETWEEN(1,10) | E211: =RANDBETWEEN(1,30) | F211: =INDEX(Suffixes!$B$2:$B$31,E211) | G211: =LOWER(SUBSTITUTE(SUBSTITUTE(SUBSTITUTE(IF(D211=1,B211&F211,IF(D211=2,B211&LEFT(F211,2),IF(D211=3,B211&"x"&F211,IF(D211=4,B211&RIGHT(B211,1)&RIGHT(B211,1),IF(D211=5,B211&"vexo",IF(D211=6,LEFT(B211,MAX(3,LEN(B211)-2))&F211,IF(D211=7,B211&"."&C211,IF(D211=8,B211&"_"&C211,IF(D211=9,B211&"zaro",B211&LEFT(C211,4)))))))))," ",""),"á","a"),"ã","a")) | H211: Pending | I211: =IF(COUNTIF($G$2:$G$1001,G211)>1,"YES","NO") | J211: =LEN(G211) | K211: =IF(OR(D211=1,D211=5,D211=6,D211=9),3,IF(OR(D211=7,D211=8,D211=10),2,1))
A212: 211 | B212: =Names!B12 | C212: =Names!C12 | D212: =RANDBETWEEN(1,10) | E212: =RANDBETWEEN(1,30) | F212: =INDEX(Suffixes!$B$2:$B$31,E212) | G212: =LOWER(SUBSTITUTE(SUBSTITUTE(SUBSTITUTE(IF(D212=1,B212&F212,IF(D212=2,B212&LEFT(F212,2),IF(D212=3,B212&"x"&F212,IF(D212=4,B212&RIGHT(B212,1)&RIGHT(B212,1),IF(D212=5,B212&"vexo",IF(D212=6,LEFT(B212,MAX(3,LEN(B212)-2))&F212,IF(D212=7,B212&"."&C212,IF(D212=8,B212&"_"&C212,IF(D212=9,B212&"zaro",B212&LEFT(C212,4)))))))))," ",""),"á","a"),"ã","a")) | H212: Pending | I212: =IF(COUNTIF($G$2:$G$1001,G212)>1,"YES","NO") | J212: =LEN(G212) | K212: =IF(OR(D212=1,D212=5,D212=6,D212=9),3,IF(OR(D212=7,D212=8,D212=10),2,1))
A213: 212 | B213: =Names!B13 | C213: =Names!C13 | D213: =RANDBETWEEN(1,10) | E213: =RANDBETWEEN(1,30) | F213: =INDEX(Suffixes!$B$2:$B$31,E213) | G213: =LOWER(SUBSTITUTE(SUBSTITUTE(SUBSTITUTE(IF(D213=1,B213&F213,IF(D213=2,B213&LEFT(F213,2),IF(D213=3,B213&"x"&F213,IF(D213=4,B213&RIGHT(B213,1)&RIGHT(B213,1),IF(D213=5,B213&"vexo",IF(D213=6,LEFT(B213,MAX(3,LEN(B213)-2))&F213,IF(D213=7,B213&"."&C213,IF(D213=8,B213&"_"&C213,IF(D213=9,B213&"zaro",B213&LEFT(C213,4)))))))))," ",""),"á","a"),"ã","a")) | H213: Pending | I213: =IF(COUNTIF($G$2:$G$1001,G213)>1,"YES","NO") | J213: =LEN(G213) | K213: =IF(OR(D213=1,D213=5,D213=6,D213=9),3,IF(OR(D213=7,D213=8,D213=10),2,1))
... A301: 300 | B301: =Names!B101 | C301: =Names!C101 | D301: =RANDBETWEEN(1,10) | E301: =RANDBETWEEN(1,30) | F301: =INDEX(Suffixes!$B$2:$B$31,E301) | G301: =LOWER(SUBSTITUTE(SUBSTITUTE(SUBSTITUTE(IF(D301=1,B301&F301,IF(D301=2,B301&LEFT(F301,2),IF(D301=3,B301&"x"&F301,IF(D301=4,B301&RIGHT(B301,1)&RIGHT(B301,1),IF(D301=5,B301&"vexo",IF(D301=6,LEFT(B301,MAX(3,LEN(B301)-2))&F301,IF(D301=7,B301&"."&C301,IF(D301=8,B301&"_"&C301,IF(D301=9,B301&"zaro",B301&LEFT(C301,4)))))))))," ",""),"á","a"),"ã","a")) | H301: Pending | I301: =IF(COUNTIF($G$2:$G$1001,G301)>1,"YES","NO") | J301: =LEN(G301) | K301: =IF(OR(D301=1,D301=5,D301=6,D301=9),3,IF(OR(D301=7,D301=8,D301=10),2,1))
...
